2024-06-20 15:51:41,247 INFO    MainThread:14412 [wandb_setup.py:_flush():76] Current SDK version is 0.17.1
2024-06-20 15:51:41,247 INFO    MainThread:14412 [wandb_setup.py:_flush():76] Configure stats pid to 14412
2024-06-20 15:51:41,247 INFO    MainThread:14412 [wandb_setup.py:_flush():76] Loading settings from C:\Users\Sai Teja\.config\wandb\settings
2024-06-20 15:51:41,248 INFO    MainThread:14412 [wandb_setup.py:_flush():76] Loading settings from c:\Users\Sai Teja\Desktop\Infosys\wandb\settings
2024-06-20 15:51:41,248 INFO    MainThread:14412 [wandb_setup.py:_flush():76] Loading settings from environment variables: {}
2024-06-20 15:51:41,248 INFO    MainThread:14412 [wandb_setup.py:_flush():76] Applying setup settings: {'_disable_service': False}
2024-06-20 15:51:41,248 INFO    MainThread:14412 [wandb_setup.py:_flush():76] Inferring run settings from compute environment: {'program': '<python with no main file>'}
2024-06-20 15:51:41,249 INFO    MainThread:14412 [wandb_setup.py:_flush():76] Applying login settings: {}
2024-06-20 15:51:41,249 INFO    MainThread:14412 [wandb_init.py:_log_setup():520] Logging user logs to c:\Users\Sai Teja\Desktop\Infosys\wandb\run-20240620_155141-rb8qfrbx\logs\debug.log
2024-06-20 15:51:41,249 INFO    MainThread:14412 [wandb_init.py:_log_setup():521] Logging internal logs to c:\Users\Sai Teja\Desktop\Infosys\wandb\run-20240620_155141-rb8qfrbx\logs\debug-internal.log
2024-06-20 15:51:41,249 INFO    MainThread:14412 [wandb_init.py:_jupyter_setup():466] configuring jupyter hooks <wandb.sdk.wandb_init._WandbInit object at 0x0000023E2ABBA2D0>
2024-06-20 15:51:41,249 INFO    MainThread:14412 [wandb_init.py:init():560] calling init triggers
2024-06-20 15:51:41,249 INFO    MainThread:14412 [wandb_init.py:init():567] wandb.init called with sweep_config: {}
config: {}
2024-06-20 15:51:41,249 INFO    MainThread:14412 [wandb_init.py:init():610] starting backend
2024-06-20 15:51:41,249 INFO    MainThread:14412 [wandb_init.py:init():614] setting up manager
2024-06-20 15:51:41,249 INFO    MainThread:14412 [backend.py:_multiprocessing_setup():105] multiprocessing start_methods=spawn, using: spawn
2024-06-20 15:51:41,269 INFO    MainThread:14412 [wandb_init.py:init():622] backend started and connected
2024-06-20 15:51:41,269 INFO    MainThread:14412 [wandb_run.py:_label_probe_notebook():1334] probe notebook
2024-06-20 15:51:41,269 INFO    MainThread:14412 [wandb_run.py:_label_probe_notebook():1344] Unable to probe notebook: 'NoneType' object has no attribute 'get'
2024-06-20 15:51:41,269 INFO    MainThread:14412 [wandb_init.py:init():711] updated telemetry
2024-06-20 15:51:41,327 INFO    MainThread:14412 [wandb_init.py:init():744] communicating run to backend with 90.0 second timeout
2024-06-20 15:53:11,632 ERROR   MainThread:14412 [wandb_init.py:init():770] encountered error: Run initialization has timed out after 90.0 sec. 
Please refer to the documentation for additional information: https://docs.wandb.ai/guides/track/tracking-faq#initstarterror-error-communicating-with-wandb-process-
2024-06-20 15:53:11,632 ERROR   MainThread:14412 [wandb_init.py:init():1181] error in wandb.init()
Traceback (most recent call last):
  File "C:\Users\Sai Teja\AppData\Local\Packages\PythonSoftwareFoundation.Python.3.12_qbz5n2kfra8p0\LocalCache\local-packages\Python312\site-packages\wandb\sdk\wandb_init.py", line 1171, in init
    return wi.init()
           ^^^^^^^^^
  File "C:\Users\Sai Teja\AppData\Local\Packages\PythonSoftwareFoundation.Python.3.12_qbz5n2kfra8p0\LocalCache\local-packages\Python312\site-packages\wandb\sdk\wandb_init.py", line 776, in init
    raise error
wandb.errors.CommError: Run initialization has timed out after 90.0 sec. 
Please refer to the documentation for additional information: https://docs.wandb.ai/guides/track/tracking-faq#initstarterror-error-communicating-with-wandb-process-
2024-06-20 15:53:18,382 INFO    Thread-10 (wrapped_target):14412 [retry.py:__call__():172] Retry attempt failed:
Traceback (most recent call last):
  File "C:\Users\Sai Teja\AppData\Local\Packages\PythonSoftwareFoundation.Python.3.12_qbz5n2kfra8p0\LocalCache\local-packages\Python312\site-packages\urllib3\connectionpool.py", line 467, in _make_request
    self._validate_conn(conn)
  File "C:\Users\Sai Teja\AppData\Local\Packages\PythonSoftwareFoundation.Python.3.12_qbz5n2kfra8p0\LocalCache\local-packages\Python312\site-packages\urllib3\connectionpool.py", line 1099, in _validate_conn
    conn.connect()
  File "C:\Users\Sai Teja\AppData\Local\Packages\PythonSoftwareFoundation.Python.3.12_qbz5n2kfra8p0\LocalCache\local-packages\Python312\site-packages\urllib3\connection.py", line 653, in connect
    sock_and_verified = _ssl_wrap_socket_and_match_hostname(
                        ^^^^^^^^^^^^^^^^^^^^^^^^^^^^^^^^^^^^
  File "C:\Users\Sai Teja\AppData\Local\Packages\PythonSoftwareFoundation.Python.3.12_qbz5n2kfra8p0\LocalCache\local-packages\Python312\site-packages\urllib3\connection.py", line 806, in _ssl_wrap_socket_and_match_hostname
    ssl_sock = ssl_wrap_socket(
               ^^^^^^^^^^^^^^^^
  File "C:\Users\Sai Teja\AppData\Local\Packages\PythonSoftwareFoundation.Python.3.12_qbz5n2kfra8p0\LocalCache\local-packages\Python312\site-packages\urllib3\util\ssl_.py", line 465, in ssl_wrap_socket
    ssl_sock = _ssl_wrap_socket_impl(sock, context, tls_in_tls, server_hostname)
               ^^^^^^^^^^^^^^^^^^^^^^^^^^^^^^^^^^^^^^^^^^^^^^^^^^^^^^^^^^^^^^^^^
  File "C:\Users\Sai Teja\AppData\Local\Packages\PythonSoftwareFoundation.Python.3.12_qbz5n2kfra8p0\LocalCache\local-packages\Python312\site-packages\urllib3\util\ssl_.py", line 509, in _ssl_wrap_socket_impl
    return ssl_context.wrap_socket(sock, server_hostname=server_hostname)
           ^^^^^^^^^^^^^^^^^^^^^^^^^^^^^^^^^^^^^^^^^^^^^^^^^^^^^^^^^^^^^^
  File "C:\Program Files\WindowsApps\PythonSoftwareFoundation.Python.3.12_3.12.1264.0_x64__qbz5n2kfra8p0\Lib\ssl.py", line 455, in wrap_socket
    return self.sslsocket_class._create(
           ^^^^^^^^^^^^^^^^^^^^^^^^^^^^^
  File "C:\Program Files\WindowsApps\PythonSoftwareFoundation.Python.3.12_3.12.1264.0_x64__qbz5n2kfra8p0\Lib\ssl.py", line 1042, in _create
    self.do_handshake()
  File "C:\Program Files\WindowsApps\PythonSoftwareFoundation.Python.3.12_3.12.1264.0_x64__qbz5n2kfra8p0\Lib\ssl.py", line 1320, in do_handshake
    self._sslobj.do_handshake()
TimeoutError: _ssl.c:983: The handshake operation timed out

The above exception was the direct cause of the following exception:

Traceback (most recent call last):
  File "C:\Users\Sai Teja\AppData\Local\Packages\PythonSoftwareFoundation.Python.3.12_qbz5n2kfra8p0\LocalCache\local-packages\Python312\site-packages\requests\adapters.py", line 667, in send
    resp = conn.urlopen(
           ^^^^^^^^^^^^^
  File "C:\Users\Sai Teja\AppData\Local\Packages\PythonSoftwareFoundation.Python.3.12_qbz5n2kfra8p0\LocalCache\local-packages\Python312\site-packages\urllib3\connectionpool.py", line 847, in urlopen
    retries = retries.increment(
              ^^^^^^^^^^^^^^^^^^
  File "C:\Users\Sai Teja\AppData\Local\Packages\PythonSoftwareFoundation.Python.3.12_qbz5n2kfra8p0\LocalCache\local-packages\Python312\site-packages\urllib3\util\retry.py", line 470, in increment
    raise reraise(type(error), error, _stacktrace)
          ^^^^^^^^^^^^^^^^^^^^^^^^^^^^^^^^^^^^^^^^
  File "C:\Users\Sai Teja\AppData\Local\Packages\PythonSoftwareFoundation.Python.3.12_qbz5n2kfra8p0\LocalCache\local-packages\Python312\site-packages\urllib3\util\util.py", line 39, in reraise
    raise value
  File "C:\Users\Sai Teja\AppData\Local\Packages\PythonSoftwareFoundation.Python.3.12_qbz5n2kfra8p0\LocalCache\local-packages\Python312\site-packages\urllib3\connectionpool.py", line 793, in urlopen
    response = self._make_request(
               ^^^^^^^^^^^^^^^^^^^
  File "C:\Users\Sai Teja\AppData\Local\Packages\PythonSoftwareFoundation.Python.3.12_qbz5n2kfra8p0\LocalCache\local-packages\Python312\site-packages\urllib3\connectionpool.py", line 491, in _make_request
    raise new_e
  File "C:\Users\Sai Teja\AppData\Local\Packages\PythonSoftwareFoundation.Python.3.12_qbz5n2kfra8p0\LocalCache\local-packages\Python312\site-packages\urllib3\connectionpool.py", line 469, in _make_request
    self._raise_timeout(err=e, url=url, timeout_value=conn.timeout)
  File "C:\Users\Sai Teja\AppData\Local\Packages\PythonSoftwareFoundation.Python.3.12_qbz5n2kfra8p0\LocalCache\local-packages\Python312\site-packages\urllib3\connectionpool.py", line 370, in _raise_timeout
    raise ReadTimeoutError(
urllib3.exceptions.ReadTimeoutError: HTTPSConnectionPool(host='api.wandb.ai', port=443): Read timed out. (read timeout=20)

During handling of the above exception, another exception occurred:

Traceback (most recent call last):
  File "C:\Users\Sai Teja\AppData\Local\Packages\PythonSoftwareFoundation.Python.3.12_qbz5n2kfra8p0\LocalCache\local-packages\Python312\site-packages\wandb\sdk\lib\retry.py", line 131, in __call__
    result = self._call_fn(*args, **kwargs)
             ^^^^^^^^^^^^^^^^^^^^^^^^^^^^^^
  File "C:\Users\Sai Teja\AppData\Local\Packages\PythonSoftwareFoundation.Python.3.12_qbz5n2kfra8p0\LocalCache\local-packages\Python312\site-packages\wandb\sdk\internal\internal_api.py", line 340, in execute
    return self.client.execute(*args, **kwargs)  # type: ignore
           ^^^^^^^^^^^^^^^^^^^^^^^^^^^^^^^^^^^^
  File "C:\Users\Sai Teja\AppData\Local\Packages\PythonSoftwareFoundation.Python.3.12_qbz5n2kfra8p0\LocalCache\local-packages\Python312\site-packages\wandb\vendor\gql-0.2.0\wandb_gql\client.py", line 52, in execute
    result = self._get_result(document, *args, **kwargs)
             ^^^^^^^^^^^^^^^^^^^^^^^^^^^^^^^^^^^^^^^^^^^
  File "C:\Users\Sai Teja\AppData\Local\Packages\PythonSoftwareFoundation.Python.3.12_qbz5n2kfra8p0\LocalCache\local-packages\Python312\site-packages\wandb\vendor\gql-0.2.0\wandb_gql\client.py", line 60, in _get_result
    return self.transport.execute(document, *args, **kwargs)
           ^^^^^^^^^^^^^^^^^^^^^^^^^^^^^^^^^^^^^^^^^^^^^^^^^
  File "C:\Users\Sai Teja\AppData\Local\Packages\PythonSoftwareFoundation.Python.3.12_qbz5n2kfra8p0\LocalCache\local-packages\Python312\site-packages\wandb\sdk\lib\gql_request.py", line 58, in execute
    request = self.session.post(self.url, **post_args)
              ^^^^^^^^^^^^^^^^^^^^^^^^^^^^^^^^^^^^^^^^
  File "C:\Users\Sai Teja\AppData\Local\Packages\PythonSoftwareFoundation.Python.3.12_qbz5n2kfra8p0\LocalCache\local-packages\Python312\site-packages\requests\sessions.py", line 637, in post
    return self.request("POST", url, data=data, json=json, **kwargs)
           ^^^^^^^^^^^^^^^^^^^^^^^^^^^^^^^^^^^^^^^^^^^^^^^^^^^^^^^^^
  File "C:\Users\Sai Teja\AppData\Local\Packages\PythonSoftwareFoundation.Python.3.12_qbz5n2kfra8p0\LocalCache\local-packages\Python312\site-packages\requests\sessions.py", line 589, in request
    resp = self.send(prep, **send_kwargs)
           ^^^^^^^^^^^^^^^^^^^^^^^^^^^^^^
  File "C:\Users\Sai Teja\AppData\Local\Packages\PythonSoftwareFoundation.Python.3.12_qbz5n2kfra8p0\LocalCache\local-packages\Python312\site-packages\requests\sessions.py", line 703, in send
    r = adapter.send(request, **kwargs)
        ^^^^^^^^^^^^^^^^^^^^^^^^^^^^^^^
  File "C:\Users\Sai Teja\AppData\Local\Packages\PythonSoftwareFoundation.Python.3.12_qbz5n2kfra8p0\LocalCache\local-packages\Python312\site-packages\requests\adapters.py", line 713, in send
    raise ReadTimeout(e, request=request)
requests.exceptions.ReadTimeout: HTTPSConnectionPool(host='api.wandb.ai', port=443): Read timed out. (read timeout=20)
